<?xml version="1.0" encoding="utf-8"?>
<!-- =================================================================================== -->
<!-- |    This document was autogenerated by xacro from rover.urdf.xacro               | -->
<!-- |    EDITING THIS FILE BY HAND IS NOT RECOMMENDED                                 | -->
<!-- =================================================================================== -->
<robot name="2WD_rover_robotics" xmlns:xacro="http://ros.org/wiki/xacro">
  <!-- Init colour -->
  <material name="black">
    <color rgba="0.0 0.0 0.0 1.0"/>
  </material>
  <material name="dark">
    <color rgba="0.3 0.3 0.3 1.0"/>
  </material>
  <material name="light_black">
    <color rgba="0.4 0.4 0.4 1.0"/>
  </material>
  <material name="blue">
    <color rgba="0.0 0.0 0.8 1.0"/>
  </material>
  <material name="green">
    <color rgba="0.0 0.8 0.0 1.0"/>
  </material>
  <material name="grey">
    <color rgba="0.5 0.5 0.5 1.0"/>
  </material>
  <material name="orange">
    <color rgba="1.0 0.423529411765 0.0392156862745 1.0"/>
  </material>
  <material name="brown">
    <color rgba="0.870588235294 0.811764705882 0.764705882353 1.0"/>
  </material>
  <material name="red">
    <color rgba="0.8 0.0 0.0 1.0"/>
  </material>
  <material name="white">
    <color rgba="1.0 1.0 1.0 1.0"/>
  </material>
  <material name="acrylic">
    <color rgba="0.9 0.9 1.0 0.6"/>
  </material>
  <gazebo reference="base_link">
    <material>Gazebo/DarkGrey</material>
  </gazebo>
  <gazebo reference="wheel_left_link">
    <mu1>0.1</mu1>
    <mu2>0.1</mu2>
    <kp>500000.0</kp>
    <kd>10.0</kd>
    <minDepth>0.001</minDepth>
    <maxVel>0.1</maxVel>
    <fdir1>1 0 0</fdir1>
    <material>Gazebo/White</material>
  </gazebo>
  <gazebo reference="wheel_right_link">
    <mu1>0.1</mu1>
    <mu2>0.1</mu2>
    <kp>500000.0</kp>
    <kd>10.0</kd>
    <minDepth>0.001</minDepth>
    <maxVel>0.1</maxVel>
    <fdir1>1 0 0</fdir1>
    <material>Gazebo/White</material>
  </gazebo>
  <gazebo reference="sheetmetal_link">
    <mu1>0.1</mu1>
    <mu2>0.1</mu2>
    <kp>1000000.0</kp>
    <kd>100.0</kd>
    <minDepth>0.001</minDepth>
    <maxVel>1.0</maxVel>
    <material>Gazebo/White</material>
  </gazebo>
  <gazebo reference="caster_back_left_link">
    <mu1>0.1</mu1>
    <mu2>0.1</mu2>
    <kp>1000000.0</kp>
    <kd>100.0</kd>
    <minDepth>0.001</minDepth>
    <maxVel>1.0</maxVel>
    <material>Gazebo/FlatBlack</material>
  </gazebo>
  <gazebo reference="caster_back_right_link">
    <mu1>0.1</mu1>
    <mu2>0.1</mu2>
    <kp>1000000.0</kp>
    <kd>100.0</kd>
    <minDepth>0.001</minDepth>
    <maxVel>1.0</maxVel>
    <material>Gazebo/FlatBlack</material>
  </gazebo>
  <gazebo reference="imu_link">
    <sensor name="imu" type="imu">
      <always_on>true</always_on>
      <visualize>false</visualize>
    </sensor>
    <material>Gazebo/Grey</material>
  </gazebo>
  <gazebo>
    <plugin filename="libgazebo_ros_diff_drive.so" name="openrover_controller">
      <commandTopic>cmd_vel</commandTopic>
      <odometryTopic>odom</odometryTopic>
      <odometryFrame>odom</odometryFrame>
      <odometrySource>world</odometrySource>
      <publishOdomTF>false</publishOdomTF>
      <robotBaseFrame>base_footprint</robotBaseFrame>
      <publishWheelTF>false</publishWheelTF>
      <publishTf>false</publishTf>
      <publishWheelJointState>false</publishWheelJointState>
      <legacyMode>false</legacyMode>
      <updateRate>10</updateRate>
      <leftJoint>wheel_left_joint</leftJoint>
      <rightJoint>wheel_right_joint</rightJoint>
      <wheelSeparation>0.287</wheelSeparation>
      <wheelDiameter>0.066</wheelDiameter>
      <wheelAcceleration>1</wheelAcceleration>
      <wheelTorque>10</wheelTorque>
      <rosDebugLevel>na</rosDebugLevel>
    </plugin>
  </gazebo>
  <gazebo>
    <plugin filename="libgazebo_ros_joint_state_publisher.so" name="openrover_caster_publisher">
      <jointName>wheel_left_joint,wheel_right_joint,caster_back_left_joint,caster_back_right_joint</jointName>
      <updateRate>30</updateRate>
    </plugin>
  </gazebo>
  <gazebo>
    <plugin filename="libgazebo_ros_imu.so" name="imu_plugin">
      <alwaysOn>true</alwaysOn>
      <bodyName>imu_link</bodyName>
      <frameName>imu_link</frameName>
      <topicName>imu/data</topicName>
      <serviceName>imu_service</serviceName>
      <gaussianNoise>0.0</gaussianNoise>
      <updateRate>30</updateRate>
      <imu>
        <noise>
          <type>gaussian</type>
          <rate>
            <mean>0.0</mean>
            <stddev>2e-4</stddev>
            <bias_mean>0.0000075</bias_mean>
            <bias_stddev>0.0000008</bias_stddev>
          </rate>
          <accel>
            <mean>0.0</mean>
            <stddev>1.7e-2</stddev>
            <bias_mean>0.1</bias_mean>
            <bias_stddev>0.001</bias_stddev>
          </accel>
        </noise>
      </imu>
    </plugin>
  </gazebo>
  <gazebo reference="base_scan">
    <material>Gazebo/FlatBlack</material>
    <sensor name="lds_lfcd_sensor" type="ray">
      <pose>0 0 0 0 0 0</pose>
      <visualize>false</visualize>
      <update_rate>13</update_rate>
      <ray>
        <scan>
          <horizontal>
            <samples>360</samples>
            <resolution>1</resolution>
            <min_angle>0.0</min_angle>
            <max_angle>6.28319</max_angle>
          </horizontal>
        </scan>
        <range>
          <min>0.120</min>
          <max>3.5</max>
          <resolution>0.015</resolution>
        </range>
        <noise>
          <type>gaussian</type>
          <mean>0.0</mean>
          <stddev>0.01</stddev>
        </noise>
      </ray>
      <plugin filename="libgazebo_ros_gpu_laser.so" name="gazebo_ros_lds_lfcd_controller">
        <topicName>scan</topicName>
        <frameName>lidar_link</frameName>
      </plugin>
    </sensor>
  </gazebo>
  <link name="base_footprint"/>
  <joint name="base_joint" type="fixed">
    <parent link="base_footprint"/>
    <child link="base_link"/>
    <origin rpy="0 0 0" xyz="0 0 0.12"/>
  </joint>
  <link name="base_link">
    <visual>
      <origin rpy="0 0 1.57" xyz="-0.142 0 0.055"/>
      <geometry>
        <mesh filename="package://openrover_demo/meshes/2WD_OpenRover.stl" scale="1 1 1"/>
        <!--
      <origin xyz="-0.142 0 0" rpy="0 0 0"/>
      <geometry>
        <box size="0.42 0.25 0.12"/>
        -->
      </geometry>
      <material name="dark"/>
    </visual>
    <collision>
      <origin rpy="0 0 0" xyz="-0.142 0 0"/>
      <geometry>
        <box size="0.42 0.25 0.12"/>
      </geometry>
    </collision>
    <inertial>
      <origin rpy="0 0 0" xyz="-0.142 0 0"/>
      <mass value="7.5"/>
      <inertia ixx="4.806e-2" ixy="0.0" ixz="0.0" iyy="1.193e-1" iyz="0.0" izz="1.493e-1"/>
    </inertial>
  </link>
  <joint name="wheel_left_joint" type="continuous">
    <parent link="base_link"/>
    <child link="wheel_left_link"/>
    <origin rpy="-1.57 0 0" xyz="0 0.179 0"/>
    <axis xyz="0 0 1"/>
  </joint>
  <link name="wheel_left_link">
    <visual>
      <origin rpy="-1.57 0 0" xyz="0 0 0"/>
      <geometry>
        <mesh filename="package://openrover_demo/meshes/left_wheel.stl" scale="1 1 1"/>
        <!--
      <origin xyz="0 0 0" rpy="0 0 3.14"/>
      <geometry>
        <cylinder length="0.07" radius="0.12"/>
        -->
      </geometry>
      <material name="black"/>
    </visual>
    <collision>
      <origin rpy="0 0 3.14" xyz="0 0 0"/>
      <geometry>
        <cylinder length="0.07" radius="0.12"/>
      </geometry>
    </collision>
    <inertial>
      <origin rpy="0 0 3.14" xyz="0 0 0"/>
      <mass value="1.525"/>
      <inertia ixx="6.723e-3" ixy="0.0" ixz="0.0" iyy="6.723e-3" iyz="0.0" izz="1.220e-2"/>
    </inertial>
  </link>
  <joint name="wheel_right_joint" type="continuous">
    <parent link="base_link"/>
    <child link="wheel_right_link"/>
    <origin rpy="-1.57 0 0" xyz="0 -0.179 0"/>
    <axis xyz="0 0 1"/>
  </joint>
  <link name="wheel_right_link">
    <visual>
      <origin rpy="1.57 0 0" xyz="0 0 0"/>
      <geometry>
        <mesh filename="package://openrover_demo/meshes/right_wheel.stl" scale="1 1 1"/>
        <!--
      <origin xyz="0 0 0" rpy="0 0 0"/>
      <geometry>
        <cylinder length="0.07" radius="0.12"/>
        -->
      </geometry>
      <material name="black"/>
    </visual>
    <collision>
      <origin rpy="0 0 0" xyz="0 0 0"/>
      <geometry>
        <cylinder length="0.07" radius="0.12"/>
      </geometry>
    </collision>
    <inertial>
      <origin rpy="0 0 0" xyz="0 0 0"/>
      <mass value="1.525"/>
      <inertia ixx="6.723e-3" ixy="0.0" ixz="0.0" iyy="6.723e-3" iyz="0.0" izz="1.220e-2"/>
    </inertial>
  </link>
  <joint name="sheetmetal_joint" type="fixed">
    <parent link="base_link"/>
    <child link="sheetmetal_link"/>
    <origin rpy="0 0 0" xyz="-0.35 0 0"/>
  </joint>
  <link name="sheetmetal_link">
    <visual>
      <origin rpy="1.57 0 -1.57" xyz="0 0 0"/>
      <geometry>
        <mesh filename="package://openrover_demo/meshes/sheetmetal_part.stl" scale="1 1 1"/>
        <!--
      <origin xyz="0 0 0" rpy="0 0 0"/>
      <geometry>
        <box size="0.065 0.4 0.008"/>
        -->
      </geometry>
      <material name="dark"/>
    </visual>
    <collision>
      <origin rpy="0 0 0" xyz="-0.007 0 0"/>
      <geometry>
        <box size="0.065 0.4 0.008"/>
      </geometry>
    </collision>
    <inertial>
      <origin xyz="0 0 0"/>
      <mass value="0.6"/>
      <inertia ixx="8.020e-3" ixy="0.0" ixz="0.0" iyy="2.313e-4" iyz="0.0" izz="8.211e-3"/>
    </inertial>
  </link>
  <joint name="plate_link_joint" type="fixed">
    <parent link="base_link"/>
    <child link="plate_link"/>
    <origin rpy="0 0 0" xyz="-0.1365 0 0.127"/>
  </joint>
  <link name="plate_link">
    <visual>
      <origin rpy="0 0 0" xyz="0 0 0"/>
      <geometry>
        <box size="0.381 0.254 0.005"/>
      </geometry>
      <material name="acrylic"/>
    </visual>
    <inertial>
      <origin xyz="0 0 0"/>
      <mass value="0.65"/>
      <inertia ixx="3.496e-3" ixy="0.0" ixz="0.0" iyy="7.864e-3" iyz="0.0" izz="1.136e-2"/>
    </inertial>
  </link>
  <joint name="imu_link_joint" type="fixed">
    <parent link="plate_link"/>
    <child link="imu_link"/>
    <origin rpy="0 0 0" xyz="0.1365 0 0.0026"/>
  </joint>
  <link name="imu_link">
    <visual>
      <origin rpy="0 0 0" xyz="0 0 0"/>
      <geometry>
        <box size="0.01 0.01 0.002"/>
      </geometry>
      <material name="blue"/>
    </visual>
    <inertial>
      <origin xyz="0 0 0"/>
      <mass value="0.04"/>
      <inertia ixx="3.467e-7" ixy="0.0" ixz="0.0" iyy="3.467e-7" iyz="0.0" izz="6.667e-7"/>
    </inertial>
  </link>
  <joint name="cpu_link_joint" type="fixed">
    <parent link="plate_link"/>
    <child link="cpu_link"/>
    <origin rpy="0 0 0" xyz="-0.0032 0 0.0275"/>
  </joint>
  <link name="cpu_link">
    <visual>
      <origin rpy="0 0 0" xyz="0 0 0"/>
      <geometry>
        <box size="0.111 0.117 0.05"/>
      </geometry>
      <material name="light_black"/>
    </visual>
    <inertial>
      <origin xyz="0 0 0"/>
      <mass value="0.64"/>
      <inertia ixx="8.634e-4" ixy="0.0" ixz="0.0" iyy="7.905e-4" iyz="0.0" izz="1.387e-3"/>
    </inertial>
  </link>
  <joint name="lidar_link_joint" type="fixed">
    <parent link="cpu_link"/>
    <child link="lidar_link"/>
    <origin rpy="0 0 0" xyz="0 0 0.0488"/>
  </joint>
  <link name="lidar_link">
    <visual>
      <origin rpy="0 0 0" xyz="0 0 0"/>
      <geometry>
        <cylinder length="0.0476" radius="0.0381"/>
      </geometry>
      <material name="light_black"/>
    </visual>
    <inertial>
      <origin xyz="0 0 0"/>
      <mass value="0.220"/>
      <inertia ixx="1.214e-4" ixy="0.0" ixz="0.0" iyy="1.214e-4" iyz="0.0" izz="1.597e-4"/>
    </inertial>
  </link>
  <joint name="caster_back_left_joint" type="continuous">
    <parent link="sheetmetal_link"/>
    <child link="caster_back_left_link"/>
    <origin rpy="0 0 0" xyz="-0.01 0.17 -0.01"/>
    <axis xyz="0 0 1"/>
  </joint>
  <link name="caster_back_left_link">
    <visual>
      <origin rpy="1.57 0 3.14" xyz="0 0 0"/>
      <geometry>
        <mesh filename="package://openrover_demo/meshes/left_caster_wheel.stl" scale="1 1 1"/>
        <!--
      <origin xyz="-0.028 0 -0.065" rpy="1.57 0 3.14"/>
      <geometry>
        <cylinder length="0.035" radius="0.048"/>
        -->
      </geometry>
      <material name="grey"/>
    </visual>
    <collision>
      <origin rpy="1.57 0 3.14" xyz="-0.028 0 -0.065"/>
      <geometry>
        <cylinder length="0.035" radius="0.048"/>
      </geometry>
    </collision>
    <inertial>
      <origin xyz="-0.005 0 -0.03"/>
      <mass value="0.41"/>
      <inertia ixx="3.841e-4" ixy="0.0" ixz="0.0" iyy="4.592e-4" iyz="0.0" izz="2.135e-4"/>
    </inertial>
  </link>
  <joint name="caster_back_right_joint" type="continuous">
    <parent link="sheetmetal_link"/>
    <child link="caster_back_right_link"/>
    <origin rpy="0 0 0" xyz="-0.01 -0.17 -0.01"/>
    <axis xyz="0 0 1"/>
  </joint>
  <link name="caster_back_right_link">
    <visual>
      <origin rpy="1.57 0 3.14" xyz="0 0 0"/>
      <geometry>
        <mesh filename="package://openrover_demo/meshes/right_caster_wheel.stl" scale="1 1 1"/>
        <!--
      <origin xyz="-0.028 0 -0.065" rpy="1.57 0 3.14"/>
      <geometry>
        <cylinder length="0.035" radius="0.048"/>
        -->
      </geometry>
      <material name="grey"/>
    </visual>
    <collision>
      <origin rpy="1.57 0 3.14" xyz="-0.028 0 -0.065"/>
      <geometry>
        <cylinder length="0.035" radius="0.048"/>
      </geometry>
    </collision>
    <inertial>
      <origin xyz="-0.005 0 -0.03"/>
      <mass value="0.41"/>
      <inertia ixx="3.841e-4" ixy="0.0" ixz="0.0" iyy="4.592e-4" iyz="0.0" izz="2.135e-4"/>
    </inertial>
  </link>
</robot>

