<?xml version="1.0" ?>
<!-- =================================================================================== -->
<!-- |    This document was autogenerated by xacro from rover.urdf.xacro               | -->
<!-- |    EDITING THIS FILE BY HAND IS NOT RECOMMENDED                                 | -->
<!-- =================================================================================== -->
<robot name="2WD_rover_robotics" xmlns:xacro="http://ros.org/wiki/xacro">
  <!-- Init colour -->
  <material name="black">
    <color rgba="0.0 0.0 0.0 1.0"/>
  </material>
  <material name="dark">
    <color rgba="0.3 0.3 0.3 1.0"/>
  </material>
  <material name="light_black">
    <color rgba="0.4 0.4 0.4 1.0"/>
  </material>
  <material name="blue">
    <color rgba="0.0 0.0 0.8 1.0"/>
  </material>
  <material name="green">
    <color rgba="0.0 0.8 0.0 1.0"/>
  </material>
  <material name="grey">
    <color rgba="0.5 0.5 0.5 1.0"/>
  </material>
  <material name="orange">
    <color rgba="1.0 0.4235294117647059 0.0392156862745098 1.0"/>
  </material>
  <material name="brown">
    <color rgba="0.8705882352941177 0.8117647058823529 0.7647058823529411 1.0"/>
  </material>
  <material name="red">
    <color rgba="0.8 0.0 0.0 1.0"/>
  </material>
  <material name="white">
    <color rgba="1.0 1.0 1.0 1.0"/>
  </material>
  <material name="acrylic">
    <color rgba="0.9 0.9 1.0 0.6"/>
  </material>
  <gazebo reference="base_link">
    <material>Gazebo/FlatBlack</material>
  </gazebo>
  <gazebo reference="sheetmetal_link">
    <material>Gazebo/FlatBlack</material>
  </gazebo>
  <gazebo reference="wheel_left_link">
    <mu1>0.7</mu1>
    <mu2>1.0</mu2>
    <kp>300000.0</kp>
    <material>Gazebo/Black</material>
  </gazebo>
  <gazebo reference="wheel_right_link">
    <mu1>0.7</mu1>
    <mu2>1.0</mu2>
    <kp>300000.0</kp>
    <material>Gazebo/Black</material>
  </gazebo>
  <gazebo reference="caster_back_left_link">
    <mu1>0.1</mu1>
    <mu2>0.6</mu2>
    <kp>200000.0</kp>
    <material>Gazebo/Grey</material>
  </gazebo>
  <gazebo reference="caster_back_right_link">
    <mu1>0.1</mu1>
    <mu2>0.6</mu2>
    <kp>200000.0</kp>
    <material>Gazebo/Grey</material>
  </gazebo>
  <gazebo reference="plate_link">
    <material>Gazebo/GreyTransparent</material>
  </gazebo>
  <gazebo reference="imu_link">
    <sensor name="gazebo_imu" type="imu">
      <always_on>true</always_on>
      <update_rate>30.0</update_rate>
      <plugin filename="libgazebo_ros_imu_sensor.so" name="gazebo_imu">
        <ros>
          <namespace>/imu</namespace>
          <argument>~/out:=data</argument>
        </ros>
        <frame_name>imu_link</frame_name>
      </plugin>
      <imu>
        <angular_velocity>
          <x>
            <noise type="gaussian">
              <mean>0.0</mean>
              <stddev>0.0052</stddev>
            </noise>
          </x>
          <y>
            <noise type="gaussian">
              <mean>0.0</mean>
              <stddev>0.0052</stddev>
            </noise>
          </y>
          <z>
            <noise type="gaussian">
              <mean>0.0</mean>
              <stddev>0.0052</stddev>
            </noise>
          </z>
        </angular_velocity>
        <linear_acceleration>
          <x>
            <noise type="gaussian">
              <mean>0.0</mean>
              <stddev>0.0015</stddev>
            </noise>
          </x>
          <y>
            <noise type="gaussian">
              <mean>0.0</mean>
              <stddev>0.0015</stddev>
            </noise>
          </y>
          <z>
            <noise type="gaussian">
              <mean>0.0</mean>
              <stddev>0.0015</stddev>
            </noise>
          </z>
        </linear_acceleration>
      </imu>
    </sensor>
    <material>Gazebo/Blue</material>
  </gazebo>
  <gazebo reference="cpu_link">
    <material>Gazebo/DarkGrey</material>
  </gazebo>
  <gazebo reference="lidar_link">
    <sensor name="gazebo_lidar" type="ray">
      <update_rate>12.0</update_rate>
      <plugin filename="libgazebo_ros_ray_sensor.so" name="gazebo_lidar">
        <ros>
          <argument>~/out:=scan</argument>
          <namespace/>
        </ros>
        <output_type>sensor_msgs/LaserScan</output_type>
        <frame_name>lidar_link</frame_name>
      </plugin>
      <ray>
        <scan>
          <horizontal>
            <samples>360</samples>
            <resolution>1</resolution>
            <min_angle>-3.14159</min_angle>
            <max_angle>3.14159</max_angle>
          </horizontal>
        </scan>
        <range>
          <min>0.120</min>
          <max>3.5</max>
          <resolution>0.015</resolution>
        </range>
        <noise>
          <type>gaussian</type>
          <mean>0.0</mean>
          <stddev>0.01</stddev>
        </noise>
      </ray>
    </sensor>
    <material>Gazebo/DarkGrey</material>
  </gazebo>
  <gazebo>
    <plugin filename="libgazebo_ros_diff_drive.so" name="gazebo_base_controller">
      <odometry_frame>odom</odometry_frame>
      <publish_odom>true</publish_odom>
      <publish_odom_tf>false</publish_odom_tf>
      <robot_base_frame>base_footprint</robot_base_frame>
      <publish_wheel_tf>false</publish_wheel_tf>
      <update_rate>15.0</update_rate>
      <left_joint>wheel_left_joint</left_joint>
      <right_joint>wheel_right_joint</right_joint>
      <wheel_separation>0.358</wheel_separation>
      <wheel_diameter>0.24</wheel_diameter>
      <max_wheel_acceleration>0.7</max_wheel_acceleration>
      <max_wheel_torque>8</max_wheel_torque>
      <ros>
        <argument>odom:=odom_raw</argument>
      </ros>
    </plugin>
  </gazebo>
  <gazebo>
    <plugin filename="libgazebo_ros_joint_state_publisher.so" name="gazebo_joint_publisher">
      <joint_name>wheel_left_joint</joint_name>
      <joint_name>wheel_right_joint</joint_name>
      <joint_name>caster_back_left_joint</joint_name>
      <joint_name>caster_back_right_joint</joint_name>
      <update_rate>30.0</update_rate>
    </plugin>
  </gazebo>
  <link name="base_footprint"/>
  <joint name="base_joint" type="fixed">
    <parent link="base_footprint"/>
    <child link="base_link"/>
    <origin rpy="0 0 0" xyz="0 0 0.12"/>
  </joint>
  <link name="base_link">
    <visual>
      <origin rpy="0 0 1.57" xyz="-0.142 0 0.055"/>
      <geometry>
        <mesh filename="package://openrover_demo/meshes/2WD_OpenRover.stl" scale="1 1 1"/>
        <!--
      <origin xyz="-0.142 0 0" rpy="0 0 0"/>
      <geometry>
        <box size="0.42 0.25 0.12"/>
        -->
      </geometry>
      <material name="dark"/>
    </visual>
    <collision>
      <origin rpy="0 0 0" xyz="-0.142 0 0"/>
      <geometry>
        <box size="0.42 0.25 0.12"/>
      </geometry>
    </collision>
    <inertial>
      <origin rpy="0 0 0" xyz="-0.142 0 0"/>
      <mass value="7.5"/>
      <inertia ixx="4.806e-2" ixy="0.0" ixz="0.0" iyy="1.193e-1" iyz="0.0" izz="1.493e-1"/>
    </inertial>
  </link>
  <joint name="wheel_left_joint" type="continuous">
    <parent link="base_link"/>
    <child link="wheel_left_link"/>
    <origin rpy="-1.57 0 0" xyz="0 0.179 0"/>
    <axis xyz="0 0 1"/>
  </joint>
  <link name="wheel_left_link">
    <visual>
      <origin rpy="-1.57 0 0" xyz="0 0 0"/>
      <geometry>
        <mesh filename="package://openrover_demo/meshes/left_wheel.stl" scale="1 1 1"/>
        <!--
      <origin xyz="0 0 0" rpy="0 0 3.14"/>
      <geometry>
        <cylinder length="0.07" radius="0.12"/>
        -->
      </geometry>
      <material name="black"/>
    </visual>
    <collision>
      <origin rpy="0 0 3.14" xyz="0 0 0"/>
      <geometry>
        <cylinder length="0.07" radius="0.12"/>
      </geometry>
    </collision>
    <inertial>
      <origin rpy="0 0 3.14" xyz="0 0 0"/>
      <mass value="1.525"/>
      <inertia ixx="6.723e-3" ixy="0.0" ixz="0.0" iyy="6.723e-3" iyz="0.0" izz="1.220e-2"/>
    </inertial>
  </link>
  <joint name="wheel_right_joint" type="continuous">
    <parent link="base_link"/>
    <child link="wheel_right_link"/>
    <origin rpy="-1.57 0 0" xyz="0 -0.179 0"/>
    <axis xyz="0 0 1"/>
  </joint>
  <link name="wheel_right_link">
    <visual>
      <origin rpy="1.57 0 0" xyz="0 0 0"/>
      <geometry>
        <mesh filename="package://openrover_demo/meshes/right_wheel.stl" scale="1 1 1"/>
        <!--
      <origin xyz="0 0 0" rpy="0 0 0"/>
      <geometry>
        <cylinder length="0.07" radius="0.12"/>
        -->
      </geometry>
      <material name="black"/>
    </visual>
    <collision>
      <origin rpy="0 0 0" xyz="0 0 0"/>
      <geometry>
        <cylinder length="0.07" radius="0.12"/>
      </geometry>
    </collision>
    <inertial>
      <origin rpy="0 0 0" xyz="0 0 0"/>
      <mass value="1.525"/>
      <inertia ixx="6.723e-3" ixy="0.0" ixz="0.0" iyy="6.723e-3" iyz="0.0" izz="1.220e-2"/>
    </inertial>
  </link>
  <joint name="sheetmetal_joint" type="fixed">
    <parent link="base_link"/>
    <child link="sheetmetal_link"/>
    <origin rpy="0 0 0" xyz="-0.35 0 0"/>
  </joint>
  <link name="sheetmetal_link">
    <visual>
      <origin rpy="1.57 0 -1.57" xyz="0 0 0"/>
      <geometry>
        <mesh filename="package://openrover_demo/meshes/sheetmetal_part.stl" scale="1 1 1"/>
        <!--
      <origin xyz="0 0 0" rpy="0 0 0"/>
      <geometry>
        <box size="0.065 0.4 0.008"/>
        -->
      </geometry>
      <material name="dark"/>
    </visual>
    <collision>
      <origin rpy="0 0 0" xyz="-0.007 0 0"/>
      <geometry>
        <box size="0.065 0.4 0.008"/>
      </geometry>
    </collision>
    <inertial>
      <origin xyz="0 0 0"/>
      <mass value="0.6"/>
      <inertia ixx="8.020e-3" ixy="0.0" ixz="0.0" iyy="2.313e-4" iyz="0.0" izz="8.211e-3"/>
    </inertial>
  </link>
  <joint name="plate_link_joint" type="fixed">
    <parent link="base_link"/>
    <child link="plate_link"/>
    <origin rpy="0 0 0" xyz="-0.1365 0 0.127"/>
  </joint>
  <link name="plate_link">
    <visual>
      <origin rpy="0 0 0" xyz="0 0 0"/>
      <geometry>
        <box size="0.381 0.254 0.005"/>
      </geometry>
      <material name="acrylic"/>
    </visual>
    <inertial>
      <origin xyz="0 0 0"/>
      <mass value="0.65"/>
      <inertia ixx="3.496e-3" ixy="0.0" ixz="0.0" iyy="7.864e-3" iyz="0.0" izz="1.136e-2"/>
    </inertial>
  </link>
  <joint name="imu_link_joint" type="fixed">
    <parent link="plate_link"/>
    <child link="imu_link"/>
    <origin rpy="0 0 0" xyz="0.1365 0 0.0026"/>
  </joint>
  <link name="imu_link">
    <visual>
      <origin rpy="0 0 0" xyz="0 0 0"/>
      <geometry>
        <box size="0.01 0.01 0.002"/>
      </geometry>
      <material name="blue"/>
    </visual>
    <inertial>
      <origin xyz="0 0 0"/>
      <mass value="0.04"/>
      <inertia ixx="3.467e-7" ixy="0.0" ixz="0.0" iyy="3.467e-7" iyz="0.0" izz="6.667e-7"/>
    </inertial>
  </link>
  <joint name="cpu_link_joint" type="fixed">
    <parent link="plate_link"/>
    <child link="cpu_link"/>
    <origin rpy="0 0 0" xyz="-0.0032 0 0.0275"/>
  </joint>
  <link name="cpu_link">
    <visual>
      <origin rpy="0 0 0" xyz="0 0 0"/>
      <geometry>
        <box size="0.111 0.117 0.05"/>
      </geometry>
      <material name="light_black"/>
    </visual>
    <inertial>
      <origin xyz="0 0 0"/>
      <mass value="0.64"/>
      <inertia ixx="8.634e-4" ixy="0.0" ixz="0.0" iyy="7.905e-4" iyz="0.0" izz="1.387e-3"/>
    </inertial>
  </link>
  <joint name="lidar_link_joint" type="fixed">
    <parent link="cpu_link"/>
    <child link="lidar_link"/>
    <origin rpy="0 0 3.14" xyz="0.10795 0 0.0635"/>
  </joint>
  <link name="lidar_link">
    <visual>
      <origin rpy="0 0 0" xyz="0 0 0"/>
      <geometry>
        <cylinder length="0.0476" radius="0.0381"/>
      </geometry>
      <material name="light_black"/>
    </visual>
    <inertial>
      <origin xyz="0 0 0"/>
      <mass value="0.220"/>
      <inertia ixx="1.214e-4" ixy="0.0" ixz="0.0" iyy="1.214e-4" iyz="0.0" izz="1.597e-4"/>
    </inertial>
  </link>
  <joint name="caster_back_left_joint" type="continuous">
    <parent link="sheetmetal_link"/>
    <child link="caster_back_left_link"/>
    <origin rpy="0 0 0" xyz="-0.01 0.17 -0.01"/>
    <axis xyz="0 0 1"/>
    <dynamics damping="0.1" friction="0.01"/>
  </joint>
  <link name="caster_back_left_link">
    <visual>
      <origin rpy="1.57 0 3.14" xyz="0 0 0"/>
      <geometry>
        <mesh filename="package://openrover_demo/meshes/left_caster_wheel.stl" scale="1 1 1"/>
        <!--
      <origin xyz="-0.028 0 -0.065" rpy="1.57 0 3.14"/>
      <geometry>
        <cylinder length="0.035" radius="0.048"/>
        -->
      </geometry>
      <material name="grey"/>
    </visual>
    <collision>
      <origin rpy="1.57 0 3.14" xyz="-0.035 0 -0.065"/>
      <geometry>
        <cylinder length="0.0035" radius="0.05"/>
      </geometry>
    </collision>
    <inertial>
      <origin xyz="-0.005 0 -0.03"/>
      <mass value="0.41"/>
      <inertia ixx="3.841e-4" ixy="0.0" ixz="0.0" iyy="4.592e-4" iyz="0.0" izz="2.135e-4"/>
    </inertial>
  </link>
  <joint name="caster_back_right_joint" type="continuous">
    <parent link="sheetmetal_link"/>
    <child link="caster_back_right_link"/>
    <origin rpy="0 0 0" xyz="-0.01 -0.17 -0.01"/>
    <axis xyz="0 0 1"/>
    <dynamics damping="0.1" friction="0.01"/>
  </joint>
  <link name="caster_back_right_link">
    <visual>
      <origin rpy="1.57 0 3.14" xyz="0 0 0"/>
      <geometry>
        <mesh filename="package://openrover_demo/meshes/right_caster_wheel.stl" scale="1 1 1"/>
        <!--
      <origin xyz="-0.028 0 -0.065" rpy="1.57 0 3.14"/>
      <geometry>
        <cylinder length="0.035" radius="0.048"/>
        -->
      </geometry>
      <material name="grey"/>
    </visual>
    <collision>
      <origin rpy="1.57 0 3.14" xyz="-0.035 0 -0.065"/>
      <geometry>
        <cylinder length="0.0035" radius="0.05"/>
      </geometry>
    </collision>
    <inertial>
      <origin xyz="-0.005 0 -0.03"/>
      <mass value="0.41"/>
      <inertia ixx="3.841e-4" ixy="0.0" ixz="0.0" iyy="4.592e-4" iyz="0.0" izz="2.135e-4"/>
    </inertial>
  </link>
</robot>

